<?xml version="1.0" encoding="utf-8"?>
<!-- This URDF was automatically created by SolidWorks to URDF Exporter! Originally created by Stephen Brawner (brawner@gmail.com) 
     Commit Version: 1.6.0-4-g7f85cfe  Build Version: 1.6.7995.38578
     For more information, please see http://wiki.ros.org/sw_urdf_exporter -->
<robot
  name="RobotBimanualV3">
  <link
    name="base_link">
    <inertial>
      <origin
        xyz="0.010321 0.00065104 0.5185"
        rpy="0 0 0" />
      <mass
        value="35.545" />
      <inertia
        ixx="1.3259"
        ixy="-1.6443E-06"
        ixz="-0.00012106"
        iyy="1.3119"
        iyz="-1.547E-06"
        izz="0.026428" />
    </inertial>
    <visual>
      <origin
        xyz="0 0 0"
        rpy="0 0 0" />
      <geometry>
        <mesh
          filename="package://RobotBimanualV3/meshes/base_link.obj" />
      </geometry>
      <material
        name="">
        <color
          rgba="0.79216 0.81961 0.93333 1" />
      </material>
    </visual>
    <collision>
      <origin
        xyz="0 0 0"
        rpy="0 0 0" />
      <geometry>
        <mesh
          filename="package://RobotBimanualV3/meshes/base_link_simplified_decomposed.obj" />
      </geometry>
    </collision>
  </link>
  <link
    name="link1">
    <inertial>
      <origin
        xyz="0.00277367 6.161E-05 0.05165334"
        rpy="0 0 0" />
      <mass
        value="0.706" />
      <inertia
        ixx="0.00074611"
        ixy="5.4E-07"
        ixz="5.3E-07"
        iyy="0.00054009"
        iyz="3.26E-06"
        izz="0.00050643" />
    </inertial>
    <visual>
      <origin
        xyz="0 0 0"
        rpy="0 0 0" />
      <geometry>
        <mesh
          filename="package://RobotBimanualV3/meshes/link1.obj" />
      </geometry>
      <material
        name="">
        <color
          rgba="1 1 1 1" />
      </material>
    </visual>
    <collision>
      <origin
        xyz="0 0 0"
        rpy="0 0 0" />
      <geometry>
        <mesh
          filename="package://RobotBimanualV3/meshes/Simplified_link1_decomposed.obj" />
      </geometry>
    </collision>
  </link>
  <joint
    name="joint1"
    type="revolute">
    <origin
      xyz="0.02 0.1037 0.8358"
      rpy="0 0 0" />
    <parent
      link="base_link" />
    <child
      link="link1" />
    <axis
      xyz="0 0 1" />
    <limit
      lower="-1.57079633"
      upper="0.87266463"
      effort="4"
      velocity="2.17" />
  </joint>
  <link
    name="link2">
    <inertial>
      <origin
        xyz="-0.00124394 -5.732E-05 0.0545228"
        rpy="0 0 0" />
      <mass
        value="0.659" />
      <inertia
        ixx="0.00064807"
        ixy="8.3E-07"
        ixz="-4.6E-07"
        iyy="0.00045162"
        iyz="-1.01E-06"
        izz="0.00043422" />
    </inertial>
    <visual>
      <origin
        xyz="0 0 0"
        rpy="0 0 0" />
      <geometry>
        <mesh
          filename="package://RobotBimanualV3/meshes/link2.obj" />
      </geometry>
      <material
        name="">
        <color
          rgba="1 1 1 1" />
      </material>
    </visual>
    <collision>
      <origin
        xyz="0 0 0"
        rpy="0 0 0" />
      <geometry>
        <mesh
          filename="package://RobotBimanualV3/meshes/Simplified_link2_decomposed.obj" />
      </geometry>
    </collision>
  </link>
  <joint
    name="joint2"
    type="revolute">
    <origin
      xyz="-0.020519 0.0080718 0.0528"
      rpy="-1.5708 0 1.5708" />
    <parent
      link="link1" />
    <child
      link="link2" />
    <axis
      xyz="0 0 1" />
    <limit
      lower="-0.87266463"
      upper="0.87266463"
      effort="4"
      velocity="2.17" />
  </joint>
  <link
    name="link3">
    <inertial>
      <origin
        xyz="-0.03505493 -0.006151 0.05438578"
        rpy="0 0 0" />
      <mass
        value="1.095" />
      <inertia
        ixx="0.00161847"
        ixy="0.00042205"
        ixz="-0.00104433"
        iyy="0.0066165"
        iyz="-0.0001917"
        izz="0.00653551" />
    </inertial>
    <visual>
      <origin
        xyz="0 0 0"
        rpy="0 0 0" />
      <geometry>
        <mesh
          filename="package://RobotBimanualV3/meshes/link3.obj" />
      </geometry>
      <material
        name="">
        <color
          rgba="0.79216 0.81961 0.93333 1" />
      </material>
    </visual>
    <collision>
      <origin
        xyz="0 0 0"
        rpy="0 0 0" />
      <geometry>
        <mesh
          filename="package://RobotBimanualV3/meshes/Simplified_link3_decomposed.obj" />
      </geometry>
    </collision>
  </link>
  <joint
    name="joint3"
    type="revolute">
    <origin
      xyz="0.014928 0 0.058031"
      rpy="-1.5708 0 -1.5708" />
    <parent
      link="link2" />
    <child
      link="link3" />
    <axis
      xyz="0 0 1" />
    <limit
      lower="-3.14159265"
      upper="0.87266463"
      effort="4"
      velocity="2.17" />
  </joint>
  <link
    name="link4">
    <inertial>
      <origin
        xyz="-0.00914828 -0.00042727 -7.12E-06"
        rpy="0 0 0" />
      <mass
        value="0.268" />
      <inertia
        ixx="9.136E-05"
        ixy="7E-08"
        ixz="-2E-08"
        iyy="0.00013894"
        iyz="0"
        izz="0.00013031" />
    </inertial>
    <visual>
      <origin
        xyz="0 0 0"
        rpy="0 0 0" />
      <geometry>
        <mesh
          filename="package://RobotBimanualV3/meshes/link4.obj" />
      </geometry>
      <material
        name="">
        <color
          rgba="0.79216 0.81961 0.93333 1" />
      </material>
    </visual>
    <collision>
      <origin
        xyz="0 0 0"
        rpy="0 0 0" />
      <geometry>
        <mesh
          filename="package://RobotBimanualV3/meshes/Simplified_link4_decomposed.obj" />
      </geometry>
    </collision>
  </link>
  <joint
    name="joint4"
    type="revolute">
    <origin
      xyz="-0.25 0 0.08318"
      rpy="0 0 1.5708" />
    <parent
      link="link3" />
    <child
      link="link4" />
    <axis
      xyz="0 0 1" />
    <limit
      lower="-0.78539816"
      upper="1.30899694"
      effort="4"
      velocity="2.17" />
  </joint>
  <link
    name="link5">
    <inertial>
      <origin
        xyz="-0.00143459 -5.019E-05 0.22261684"
        rpy="0 0 0" />
      <mass
        value="0.285" />
      <inertia
        ixx="0.00170458"
        ixy="1.5E-07"
        ixz="-2.111E-05"
        iyy="0.00168732"
        iyz="-5.6E-07"
        izz="7.029E-05" />
    </inertial>
    <visual>
      <origin
        xyz="0 0 0"
        rpy="0 0 0" />
      <geometry>
        <mesh
          filename="package://RobotBimanualV3/meshes/link5.obj" scale="0.9 0.9 1" />
      </geometry>
      <material
        name="">
        <color
          rgba="0.79216 0.81961 0.93333 1" />
      </material>
    </visual>
    <collision>
      <origin
        xyz="0 0 0"
        rpy="0 0 0" />
      <geometry>
        <mesh
          filename="package://RobotBimanualV3/meshes/Simplified_link5_decomposed.obj" scale="0.9 0.9 1"  />
      </geometry>
    </collision>
  </link>
  <joint
    name="joint5"
    type="revolute">
    <origin
      xyz="0.014 0 0"
      rpy="-1.5708 0 -1.5708" />
    <parent
      link="link4" />
    <child
      link="link5" />
    <axis
      xyz="0 0 1" />
    <limit
      lower="-3.66519143"
      upper="3.66519143"
      effort="1"
      velocity="2.17" />
  </joint>
  <link
    name="link6">
    <inertial>
      <origin
        xyz="1.96220729248298E-08 0.0306524460714315 -0.00427523962371945"
        rpy="0 0 0" />
      <mass
        value="0.0592889440404456" />
      <inertia
        ixx="3.59276003023524E-05"
        ixy="-8.27592263137854E-11"
        ixz="1.05919137360094E-10"
        iyy="2.26884378809268E-05"
        iyz="8.10619055547192E-06"
        izz="4.38778249475006E-05" />
    </inertial>
    <visual>
      <origin
        xyz="0 0 0"
        rpy="0 0 0" />
      <geometry>
        <mesh
          filename="package://RobotBimanualV3/meshes/V2link6_hand.obj" />
      </geometry>
      <material
        name="">
        <color
          rgba="0.823529411764706 0.823529411764706 0.823529411764706 1" />
      </material>
    </visual>
    <collision>
      <origin
        xyz="0 0 0"
        rpy="0 0 0" />
      <geometry>
        <mesh
          filename="package://RobotBimanualV3/meshes/V2link6_hand_coacd.obj" />
      </geometry>
    </collision>
  </link>
  <joint
    name="joint6"
    type="revolute">
    <origin
      xyz="0.0141500000000001 0 0.2633"
      rpy="1.5707963267949 0 1.5707963267949" />
    <parent
      link="link5" />
    <child
      link="link6" />
    <axis
      xyz="0 0 1" />
    <limit
      lower="-2.0944"
      upper="2.0944"
      effort="1"
      velocity="2.17" />
  </joint>
  <link
    name="link6_finger">
    <inertial>
      <origin
        xyz="0.0714463212232544 -6.31832618863681E-08 0.0190000024252155"
        rpy="0 0 0" />
      <mass
        value="0.00984991794949639" />
      <inertia
        ixx="4.60166664635759E-07"
        ixy="-1.47219073587769E-13"
        ixz="-1.8754366442688E-13"
        iyy="1.24446354258398E-06"
        iyz="6.01507600040525E-14"
        izz="1.37994743489344E-06" />
    </inertial>
    <visual>
      <origin
        xyz="0 0 0"
        rpy="0 0 0" />
      <geometry>
        <mesh
          filename="package://RobotBimanualV3/meshes/V2link6_finger.obj" />
      </geometry>
      <material
        name="">
        <color
          rgba="0.823529411764706 0.823529411764706 0.823529411764706 1" />
      </material>
    </visual>
    <collision>
      <origin
        xyz="0 0 0"
        rpy="0 0 0" />
      <geometry>
        <mesh
          filename="package://RobotBimanualV3/meshes/V2link6_finger_coacd.obj" />
      </geometry>
    </collision>
  </link>
  <joint
    name="joint_gripper"
    type="fixed">
    <origin
      xyz="0 0 -0.0290000000000001"
      rpy="0 0 1.57079632679489" />
    <parent
      link="link6" />
    <child
      link="link6_finger" />
    <axis
      xyz="0 0 0" />
  </joint>
  <link name="tool1">
    <inertial>
      <origin
        xyz="0 0 0"
        rpy="0 0 0" />
      <mass
        value="0" />
      <inertia
        ixx="0"
        ixy="0"
        ixz="0"
        iyy="0"
        iyz="0"
        izz="0" />
    </inertial>
  </link>
  <joint name="tool1_frame" type="fixed">
    <origin xyz="0.0 0.0875 -0.01" rpy="0 0 0" />
    <parent link="link6" />
    <child link="tool1" />
  </joint>
</robot>